<?xml version="1.0"?>
<robot xmlns:xacro="http://www.ros.org/wiki/xacro" name="robot2_xacro">
<xacro:include filename="$(find robot1_description)/urdf/robot2.gazebo"/>
					
	<xacro:property name="length_wheel" value="0.05" />
	<xacro:property name="radius_wheel" value="0.05" />

	<xacro:macro name="default_inertial" params="mass">
               <inertial>
                       <mass value="${mass}" />
                       <inertia ixx="1.0" ixy="0.0" ixz="0.0"
                                iyy="1.0" iyz="0.0"
                                izz="1.0" />
               </inertial>
	</xacro:macro>

        <xacro:macro name="wheel_geometry">
		<geometry>
       			<cylinder length="${length_wheel}" radius="${radius_wheel}"/>
     		</geometry>
	</xacro:macro>

	<link name="base_link">
   		<visual>
     			<geometry>
       				<box size="0.2 .3 .1"/>
     			</geometry>
			<origin rpy="0 0 0" xyz="0 0 0.05"/>
			<material name="white">
				<color rgba="1 1 1 1"/>
			</material>
   		</visual>
		<collision>
			<geometry>
       				<box size="0.2 .3 0.1"/>
			</geometry>
		</collision>
		<xacro:default_inertial mass="10"/>
				
 	</link>

 	<link name="wheel_1">
   		<visual>
     			<xacro:wheel_geometry />
			<origin rpy="0 1.5 0" xyz="0.0 0.0 0"/>
   			<material name="black">
				<color rgba="0 0 0 1"/>
			</material>
		</visual>
		<collision>
			<xacro:wheel_geometry />
		</collision>
		<xacro:default_inertial mass="1"/>
 	</link>

 	<link name="wheel_2">
   		<visual>
     			<xacro:wheel_geometry />
			<origin rpy="0 1.5 0" xyz="-0.0 0.0 0"/>
   			<material name="black"/>
   		</visual>
		<collision>
			<xacro:wheel_geometry />
		</collision>
		<xacro:default_inertial mass="1"/>
 	</link>
    
 	<link name="wheel_3">
   		<visual>
 			<xacro:wheel_geometry />
			<origin rpy="0 1.5 0" xyz="0.0 -0.0 0"/>
   			<material name="black"/>
   		</visual>
		<collision>
			<xacro:wheel_geometry />
		</collision>
		<xacro:default_inertial mass="1"/>
 	</link>

 	<link name="wheel_4">
   		<visual>
  			 <xacro:wheel_geometry />
			<origin rpy="0 1.5 0" xyz="-0.0 -0.0 0"/>
   			<material name="black"/>
   		</visual>
		<collision>
			<xacro:wheel_geometry />
		</collision>
		<xacro:default_inertial mass="1"/>
 	</link>

 	<joint name="base_to_wheel1" type="continuous">
		<parent link="base_link"/>
		<child link="wheel_1"/>
                <axis xyz="1 0 0"/>
		<origin xyz="0.1 0.1 0"/>
	</joint>
	
	<joint name="base_to_wheel2" type="continuous">
		<parent link="base_link"/>
		<child link="wheel_2"/>
                <axis xyz="1 0 0"/>
		<origin xyz="-0.1 0.1 0"/>
	</joint>
	
	<joint name="base_to_wheel3" type="continuous">
		<parent link="base_link"/>
		<child link="wheel_3"/>
                <axis xyz="1 0 0"/>
		<origin xyz="0.1 -0.1 0"/>
	</joint>
	
	<joint name="base_to_wheel4" type="continuous">
		<parent link="base_link"/>
		<child link="wheel_4"/>
                <axis xyz="1 0 0"/>
		<origin xyz="-0.1 -0.1 0"/>
	</joint>
</robot>
