<?xml version="1.0"?>
<robot name="Robot1">
	<link name="base_link">
		<visual>
			<geometry>
				<box size="0.2 0.3 0.1"/>
			</geometry>
			<origin rpy="0 0 0" xyz="0 0 0.05"/>
			<material name="white">
				<color rgba="1 1 1 1"/>
			</material>
		</visual>
	</link>
	
	<link name="wheel_1">
         <visual>
			<geometry>
				<cylinder length="0.05" radius="0.05"/>
           </geometry>
			<origin rpy="0 1.57 0" xyz="0.0 0.0 0"/>
			<material name="black">
				<color rgba="0 0 0 1"/>
			</material>
		</visual>
	</link> 
	
	<link name="wheel_2">
		<visual>
			<geometry>
				<cylinder length="0.05" radius="0.05"/>
           </geometry>
           <origin rpy="0 1.57 0" xyz="0.0 0.0 0"/>
			<material name="black"/>
		</visual>
	</link>
	
	<link name="wheel_3">
		<visual>
			<geometry>
				<cylinder length="0.05" radius="0.05"/>
			</geometry>
			<origin rpy="0 1.57 0" xyz="0.0 0.0 0"/>
			<material name="black"/>
		</visual>
	</link>
	
	<link name="wheel_4">
		<visual>
			<geometry>
				<cylinder length="0.05" radius="0.05"/>
			</geometry>
			<origin rpy="0 1.57 0" xyz="-0.0 0.0 0"/>
			<material name="black"/>
		</visual>
	</link>

        <link name="arm_base">
		<visual>
			<geometry>
				<box size="0.1 .1 .1"/>
			</geometry>
			<origin rpy="0 0 0" xyz="0 0 0.1"/>
			<material name="white">
				<color rgba="1 1 1 1"/>
			</material>
		</visual>
	</link>

	<link name="arm_1">
		<visual>
			<geometry>
				<box size="0.05 .05 0.5"/>
			</geometry>
			<origin rpy="0 0 0" xyz="0 0 0.25"/>
			<material name="white">
			<color rgba="1 1 1 1"/>
			</material>
		</visual>
	</link>
	
	<link name="arm_2">
		<visual>
			<geometry>
				<box size="0.05 0.05 0.5"/>
			</geometry>
			<origin rpy="0 0 0" xyz="0.06 0 0.15"/>
			<material name="white">
			<color rgba="1 1 1 1"/>
			</material>
		</visual>
	</link>

	<joint name="base_to_wheel1" type="continuous">
		<parent link="base_link"/>
		<child link="wheel_1"/>
                <axis xyz="1 0 0"/>
		<origin xyz="0.1 0.1 0"/>
	</joint>
	
	<joint name="base_to_wheel2" type="continuous">
		<parent link="base_link"/>
		<child link="wheel_2"/>
                <axis xyz="1 0 0"/>
		<origin xyz="-0.1 0.1 0"/>
	</joint>
	
	<joint name="base_to_wheel3" type="continuous">
		<parent link="base_link"/>
		<child link="wheel_3"/>
                <axis xyz="1 0 0"/>
		<origin xyz="0.1 -0.1 0"/>
	</joint>
	
	<joint name="base_to_wheel4" type="continuous">
		<parent link="base_link"/>
		<child link="wheel_4"/>
                <axis xyz="1 0 0"/>
		<origin xyz="-0.1 -0.1 0"/>
	</joint>

        <joint name="base_to_arm_base" type="continuous">
		<parent link="base_link"/>
		<child link="arm_base"/>
		<axis xyz="0 0 1"/>
		<origin xyz="0 0 0"/>
	</joint>

        <joint name="arm_1_to_arm_base" type="revolute">
		<parent link="arm_base"/>
		<child link="arm_1"/>
		<axis xyz="1 0 0"/>
		<origin xyz="0 0 0.15"/>
		<limit effort ="100.0" lower="-1.0" upper="1.0" velocity="0.5"/>
	</joint>

       <joint name="arm_2_to_arm_1" type="revolute">
		<parent link="arm_1"/>
		<child link="arm_2"/>
		<axis xyz="1 0 0"/>
		<origin xyz="0.0 0 0.45"/>
		<limit effort ="100.0" lower="-2.5" upper="2.5" velocity="0.5"/>
	</joint>
</robot>
	
