<?xml version="1.0"?>
<robot xmlns:xacro="http://www.ros.org/wiki/xacro" name="robot4_xacro">
<xacro:include filename="$(find robot1_description)/urdf/robot4.gazebo"/>
					
	<xacro:property name="length_wheel" value="0.1" />
	<xacro:property name="radius_wheel" value="0.1" />

	<xacro:macro name="default_inertial" params="mass">
               <inertial>
                       <mass value="${mass}" />
                       <inertia ixx="1.0" ixy="0.0" ixz="0.0"
                                iyy="1.0" iyz="0.0"
                                izz="1.0" />
               </inertial>
	</xacro:macro>

        <xacro:macro name="wheel_geometry">
		<geometry>
       			<cylinder length="${length_wheel}" radius="${radius_wheel}"/>
     		</geometry>
	</xacro:macro>

	<link name="base_link">
   		<visual>
     			<geometry>
       				<box size="0.2 .3 .1"/>
     			</geometry>
			<origin rpy="0 0 0" xyz="0 0 0.05"/>
			<material name="white">
				<color rgba="1 1 1 1"/>
			</material>
   		</visual>
		<collision>
			<geometry>
       				<box size="0.2 .3 0.1"/>
			</geometry>
		</collision>
		<xacro:default_inertial mass="10"/>
				
 	</link>

 	<link name="wheel_1">
   		<visual>
     			<xacro:wheel_geometry />
			<origin rpy="0 1.5707 0" xyz="0.0 0.0 0"/>
   			<material name="black">
				<color rgba="0 0 0 1"/>
			</material>
		</visual>
		<collision>
			<xacro:wheel_geometry />
		</collision>
		<xacro:default_inertial mass="1"/>
 	</link>

 	<link name="wheel_2">
   		<visual>
     			<xacro:wheel_geometry />
			<origin rpy="0 1.5707 0" xyz="-0.0 0.0 0"/>
   			<material name="black"/>
   		</visual>
		<collision>
			<xacro:wheel_geometry />
		</collision>
		<xacro:default_inertial mass="1"/>
 	</link>
    
 	<link name="wheel_3">
   		<visual>
 			<xacro:wheel_geometry />
			<origin rpy="0 1.5707 0" xyz="0.0 -0.0 0"/>
   			<material name="black"/>
   		</visual>
		<collision>
			<xacro:wheel_geometry />
		</collision>
		<xacro:default_inertial mass="1"/>
 	</link>

 	<link name="wheel_4">
   		<visual>
  			 <xacro:wheel_geometry />
			<origin rpy="0 1.5707 0" xyz="-0.0 -0.0 0"/>
   			<material name="black"/>
   		</visual>
		<collision>
			<xacro:wheel_geometry />
		</collision>
		<xacro:default_inertial mass="1"/>
 	</link>

 	<joint name="base_to_wheel1" type="continuous">
		<parent link="base_link"/>
		<child link="wheel_1"/>
                <axis xyz="1 0 0"/>
		<origin xyz="0.1 0.1 0"/>
	</joint>
	
	<joint name="base_to_wheel2" type="continuous">
		<parent link="base_link"/>
		<child link="wheel_2"/>
                <axis xyz="1 0 0"/>
		<origin xyz="-0.1 0.1 0"/>
	</joint>
	
	<joint name="base_to_wheel3" type="continuous">
		<parent link="base_link"/>
		<child link="wheel_3"/>
                <axis xyz="1 0 0"/>
		<origin xyz="0.1 -0.1 0"/>
	</joint>
	
	<joint name="base_to_wheel4" type="continuous">
		<parent link="base_link"/>
		<child link="wheel_4"/>
                <axis xyz="1 0 0"/>
		<origin xyz="-0.1 -0.1 0"/>
	</joint>

        <!-- Camera -->
	  <link name="camera_link">
	    <collision>
	      <origin xyz="0 0 0" rpy="0 0 0"/>
	      <geometry>
		<box size="0.05 0.05 0.05"/>
	      </geometry>
	    </collision>

	    <visual>
	      <origin xyz="0 0 0" rpy="0 0 0"/>
	      <geometry>
		<box size="0.05 0.05 0.05"/>
	      </geometry>
	      <material name="red">
		<color rgba="1 0 0 1"/>
	      </material>
	    </visual>

	    <inertial>
	      <mass value="1e-5" />
	      <origin xyz="0 0 0" rpy="0 0 0"/>
	      <inertia ixx="1e-6" ixy="0" ixz="0" iyy="1e-6" iyz="0" izz="1e-6" />
	    </inertial>
	  </link>

    	 <joint name="camera_joint" type="fixed">
	    <axis xyz="0 1 0" />
	    <origin xyz="0.125 0 0.125" rpy="0 0 0"/>
	    <parent link="base_link"/>
	    <child link="camera_link"/>
	  </joint>

	
	<gazebo>
	  <plugin name="skid_steer_drive_controller" filename="libgazebo_ros_skid_steer_drive.so">
	    <updateRate>100.0</updateRate>
	    <robotNamespace>/robot</robotNamespace>
	    <leftFrontJoint>base_to_wheel1</leftFrontJoint>
	    <rightFrontJoint>base_to_wheel3</rightFrontJoint>
	    <leftRearJoint>base_to_wheel2</leftRearJoint>
	    <rightRearJoint>base_to_wheel4</rightRearJoint>
	    <wheelDiameter>0.1</wheelDiameter>
	    <robotBaseFrame>base_link</robotBaseFrame>
	    <torque>2</torque>
	    <topicName>cmd_vel</topicName>
	    <broadcastTF>0</broadcastTF>
	  </plugin>
	</gazebo>
       
</robot>
